<mujoco model="humanoid">

  <default>
    <motor ctrlrange="-1 1" ctrllimited="true"/>
    <default class="body">
      <joint type="hinge" damping="0.1" stiffness="5" armature=".007" limited="true" solimplimit="0 .99 .01"/>
    </default>
  </default>

  <asset>
    <mesh name="pelvis" file="./geom_male/pelvis.obj"></mesh>
    <mesh name="left_thigh" file="./geom_male/left_thigh.obj"></mesh>
    <mesh name="left_shin" file="./geom_male/left_shin.obj"></mesh>
    <mesh name="left_foot" file="./geom_male/left_foot.obj"></mesh>
    <mesh name="right_thigh" file="./geom_male/right_thigh.obj"></mesh>
    <mesh name="right_shin" file="./geom_male/right_shin.obj"></mesh>
    <mesh name="right_foot" file="./geom_male/right_foot.obj"></mesh>
    <mesh name="torso" file="./geom_male/torso.obj"></mesh>
    <mesh name="spine" file="./geom_male/spine.obj"></mesh>
    <mesh name="chest" file="./geom_male/chest.obj"></mesh>
    <mesh name="neck" file="./geom_male/neck.obj"></mesh>
    <mesh name="head" file="./geom_male/head.obj"></mesh>
    <mesh name="left_clavicle" file="./geom_male/left_clavicle.obj"></mesh>
    <mesh name="left_upper_arm" file="./geom_male/left_upper_arm.obj"></mesh>
    <mesh name="left_lower_arm" file="./geom_male/left_lower_arm.obj"></mesh>
    <mesh name="left_hand_part_1_palm" file="./geom_male/left_hand_part_1_palm.obj"></mesh>
    <mesh name="left_hand_part_2_finger" file="./geom_male/left_hand_part_2_finger.obj"></mesh>
    <mesh name="right_clavicle" file="./geom_male/right_clavicle.obj"></mesh>
    <mesh name="right_upper_arm" file="./geom_male/right_upper_arm.obj"></mesh>
    <mesh name="right_lower_arm" file="./geom_male/right_lower_arm.obj"></mesh>
    <mesh name="right_hand_part_1_palm" file="./geom_male/right_hand_part_1_palm.obj"></mesh>
    <mesh name="right_hand_part_2_finger" file="./geom_male/right_hand_part_2_finger.obj"></mesh>
  </asset>

  <worldbody>
    <body name="pelvis" pos="0.0011677212314680219 -0.3668408691883087 0.012669074349105358" childclass="body">
      <freejoint name="root"/>
      <inertial pos="-0.002401980306377003 -0.01547640389225317 -0.024748383962700314" quat="1 0 0 0" mass="10.0" diaginertia="1e-05 1e-05 1e-05"></inertial>
      <geom name="pelvis" type="mesh" pos="-0.002401980306377003 -0.01547640389225317 -0.024748383962700314" quat="1 0 0 0" mesh="pelvis"/>

      <body name="left_thigh" pos="0.05614368990063667 -0.09454166889190674 -0.023474548012018204">
        <joint name="left_hip_x" pos="0 0 0" axis="1 0 0" range="-180 180" stiffness="500" damping="50" armature=".02"/>
        <joint name="left_hip_y" pos="0 0 0" axis="0 1 0" range="-180 180"  stiffness="500" damping="50" armature=".02"/>
        <joint name="left_hip_z" pos="0 0 0" axis="0 0 1" range="-180 180"  stiffness="500" damping="50" armature=".02"/>
        <inertial pos="0.03547837360100287 -0.1779133050887918 0.010134188022343416" quat="1 0 0 0" mass="4.5" diaginertia="1e-05 1e-05 1e-05"></inertial>
        <geom name="left_thigh" type="mesh" pos="0.03547837360100287 -0.1779133050887918 0.010134188022343416" mesh="left_thigh"/>
      
        <body name="left_shin" pos="0.06722913682460785 -0.39686819911003113 -0.00665436964482069">
          <joint name="left_knee_x" pos="0 0 0" axis="1 0 0" range="-180 180" stiffness="500" damping="50" armature=".02"/>
          <joint name="left_knee_y" pos="0 0 0" axis="0 1 0" range="-180 180" stiffness="500" damping="50" armature=".02"/>
          <joint name="left_knee_z" pos="0 0 0" axis="0 0 1" range="-180 180" stiffness="500" damping="50" armature=".02"/>
          <inertial pos="-0.022855261181029516 -0.16690465180590466 -0.027590112434318602" quat="1 0 0 0" mass="3.0" diaginertia="1e-05 1e-05 1e-05"></inertial>
          <geom name="left_shin" type="mesh" pos="-0.022855261181029516 -0.16690465180590466 -0.027590112434318602" mesh="left_shin"/>

          <body name="left_foot" pos="-0.045593924820423126 -0.42128586769104004 -0.041146427392959595">
            <joint name="left_ankle_x" pos="0 0 0" axis="1 0 0" range="-180 180" stiffness="400" damping="40" armature=".01"/>
            <joint name="left_ankle_y" pos="0 0 0" axis="0 1 0" range="-180 180" stiffness="400" damping="40" armature=".01"/>
            <joint name="left_ankle_z" pos="0 0 0" axis="0 0 1" range="-180 180" stiffness="400" damping="40" armature=".01"/>
            <inertial pos="0.0264212060211068 -0.042774777552282726 0.06463103515272131" quat="1 0 0 0" mass="1.0" diaginertia="1e-05 1e-05 1e-05"></inertial>
            <geom name="left_foot" type="mesh" pos="0.0264212060211068 -0.042774777552282726 0.06463103515272131" mesh="left_foot"/>
          </body>
        </body>
      </body>

      <body name="right_thigh" pos="-0.05786965414881706 -0.10516685247421265 -0.016558833420276642">
        <joint name="right_hip_x" pos="0 0 0" axis="1 0 0" range="-180 180" stiffness="500" damping="50" armature=".02"/>
        <joint name="right_hip_y" pos="0 0 0" axis="0 1 0" range="-180 180"  stiffness="500" damping="50" armature=".02"/>
        <joint name="right_hip_z" pos="0 0 0" axis="0 0 1" range="-180 180"  stiffness="500" damping="50" armature=".02"/>
        <inertial pos="-0.036922064196151114 -0.1640598544700304 0.0036314986002540365" quat="1 0 0 0" mass="4.5" diaginertia="1e-05 1e-05 1e-05"></inertial>
        <geom name="right_thigh" type="mesh" pos="-0.036922064196151114 -0.1640598544700304 0.0036314986002540365" mesh="right_thigh"/>

        <body name="right_shin" pos="-0.05072679743170738 -0.37982121109962463 -0.01445161271840334">
          <joint name="right_knee_x" pos="0 0 0" axis="1 0 0" range="-180 180" stiffness="500" damping="50" armature=".02"/>
          <joint name="right_knee_y" pos="0 0 0" axis="0 1 0" range="-180 180" stiffness="500" damping="50" armature=".02"/>
          <joint name="right_knee_z" pos="0 0 0" axis="0 0 1" range="-180 180" stiffness="500" damping="50" armature=".02"/>
          <inertial pos="0.006331024734891823 -0.15729807612933164 -0.024948200958339575" quat="1 0 0 0" mass="3.0" diaginertia="1e-05 1e-05 1e-05"></inertial>
          <geom name="right_shin" type="mesh" pos="0.006331024734891823 -0.15729807612933164 -0.024948200958339575" mesh="right_shin"/>
        
          <body name="right_foot" pos="0.017154879868030548 -0.43491196632385254 -0.0399375781416893">
            <joint name="right_ankle_x" pos="0 0 0" axis="1 0 0" range="-180 180" stiffness="400" damping="40" armature=".01"/>
            <joint name="right_ankle_y" pos="0 0 0" axis="0 1 0" range="-180 180" stiffness="400" damping="40" armature=".01"/>
            <joint name="right_ankle_z" pos="0 0 0" axis="0 0 1" range="-180 180" stiffness="400" damping="40" armature=".01"/>
            <inertial pos="-0.014579158728331322 -0.028659720274886887 0.06202511261753508" quat="1 0 0 0" mass="1.0" diaginertia="1e-05 1e-05 1e-05"></inertial>
            <geom name="right_foot" type="mesh" pos="-0.014579158728331322 -0.028659720274886887 0.06202511261753508" mesh="right_foot"/>
          </body>
        </body>
      </body>

      <body name="torso" pos="-0.00133613683283329 0.11041679978370667 -0.03792468458414078">
        <joint name="abdomen_x" pos="0 0 0" axis="1 0 0" range="-180 180" stiffness="1000" damping="100" armature=".02"/>
        <joint name="abdomen_y" pos="0 0 0" axis="0 1 0" range="-180 180" stiffness="1000" damping="100" armature=".02"/>
        <joint name="abdomen_z" pos="0 0 0" axis="0 0 1" range="-180 180" stiffness="1000" damping="100" armature=".02"/>
        <inertial pos="0.009877896181456966 0.04960698877902721 0.04448446537404187" quat="1 0 0 0" mass="4.0" diaginertia="1e-05 1e-05 1e-05"></inertial>
        <geom name="torso" type="mesh" pos="0.009877896181456966 0.04960698877902721 0.04448446537404187" mesh="torso"/>

        <body name="spine" pos="0.010209237225353718 0.15097127854824066 0.00444234162569046">
          <joint name="spine_x" pos="0 0 0" axis="1 0 0" range="-180 180" stiffness="500" damping="50" armature=".02"/>
          <joint name="spine_y" pos="0 0 0" axis="0 1 0" range="-180 180" stiffness="500" damping="50" armature=".02"/>
          <joint name="spine_z" pos="0 0 0" axis="0 0 1" range="-180 180" stiffness="500" damping="50" armature=".02"/>
          <inertial pos="-0.03632897290997099 -0.00014949722504902307 0.01882986988630209" quat="1 0 0 0" mass="4.0" diaginertia="1e-05 1e-05 1e-05"></inertial>
          <geom name="spine" type="mesh" pos="-0.03632897290997099 -0.00014949722504902307 0.01882986988630209" mesh="spine"/>
        
          <body name="chest" pos="-0.008991977199912071 0.05784686654806137 0.022669697180390358">
            <joint name="chest_x" pos="0 0 0" axis="1 0 0" range="-180 180" stiffness="500" damping="50" armature=".02"/>
            <joint name="chest_y" pos="0 0 0" axis="0 1 0" range="-180 180" stiffness="500" damping="50" armature=".02"/>
            <joint name="chest_z" pos="0 0 0" axis="0 0 1" range="-180 180" stiffness="500" damping="50" armature=".02"/>
            <inertial pos="0.012089941909987727 0.06590164676062675 -0.034032804851286194" quat="1 0 0 0" mass="4.0" diaginertia="1e-05 1e-05 1e-05"></inertial>
            <geom name="chest" type="mesh" pos="0.012089941909987727 0.06590164676062675 -0.034032804851286194" mesh="chest"/>
          
            <body name="neck" pos="-0.009582404047250748 0.166020929813385 -0.027240406721830368">
              <joint name="neck_x" axis="1 0 0" range="-180 180" stiffness="100" damping="10" armature=".01"/>
              <joint name="neck_y" axis="0 1 0" range="-180 180" stiffness="100" damping="10" armature=".01"/>
              <joint name="neck_z" axis="0 0 1" range="-180 180" stiffness="100" damping="10" armature=".01"/>
              <inertial pos="0.00675619345841999 0.07350885457710714 0.003625194269338933" quat="1 0 0 0" mass="1.0" diaginertia="1e-05 1e-05 1e-05"></inertial>
              <geom name="neck" type="mesh" pos="0.00675619345841999 0.07350885457710714 0.003625194269338933" mesh="neck"/>
          
              <body name="head" pos="0.02290351688861847 0.16071966290473938 0.022939788177609444">
                <joint name="head_x" axis="1 0 0" range="-180 180" stiffness="100" damping="10" armature=".01"/>
                <joint name="head_y" axis="0 1 0" range="-180 180" stiffness="100" damping="10" armature=".01"/>
                <joint name="head_z" axis="0 0 1" range="-180 180" stiffness="100" damping="10" armature=".01"/>
                <inertial pos="-0.01437050265995752 0.03826754825468837 -0.003137605668428297" quat="1 0 0 0" mass="3.0" diaginertia="1e-05 1e-05 1e-05"></inertial>
                <geom name="head" type="mesh" pos="-0.01437050265995752 0.03826754825468837 -0.003137605668428297" mesh="head"/>
              </body>
            </body>

            <body name="left_clavicle" pos="0.04242061823606491 0.07627739012241364 -0.005254914052784443">
              <joint name="left_clavicle_x" axis="1 0 0" range="-180 180"  stiffness="400" damping="40" armature=".02"/>
              <joint name="left_clavicle_y" axis="0 1 0" range="-180 180"  stiffness="400" damping="40" armature=".02"/>
              <joint name="left_clavicle_z" axis="0 0 1" range="-180 180"  stiffness="400" damping="40" armature=".02"/>
              <inertial pos="0.11923153105174604 0.05159505275767999 -0.04980270657948168" quat="1 0 0 0" mass="1.0" diaginertia="1e-05 1e-05 1e-05"></inertial>
              <geom name="left_clavicle" type="mesh" pos="0.11923153105174604 0.05159505275767999 -0.04980270657948168" mesh="left_clavicle"/>

              <body name="left_upper_arm" pos="0.1409456580877304 0.060416869819164276 -0.01489903312176466">
                <joint name="left_shoulder_x" axis="1 0 0" range="-180 180"  stiffness="400" damping="40" armature=".02"/>
                <joint name="left_shoulder_y" axis="0 1 0" range="-180 180" stiffness="400" damping="40" armature=".02"/>
                <joint name="left_shoulder_z" axis="0 0 1" range="-180 180" stiffness="400" damping="40" armature=".02"/>
                <inertial pos="0.12180196435180407 -0.03684507115838842 -0.03032523814389514" quat="1 0 0 0" mass="1.5" diaginertia="1e-05 1e-05 1e-05"></inertial>
                <geom name="left_upper_arm" type="mesh" pos="0.12180196435180407 -0.03684507115838842 -0.03032523814389514" mesh="left_upper_arm"/>

                <body name="left_lower_arm" pos="0.25474870204925537 -0.0761655867099762 -0.0454922690987587">
                  <joint name="left_elbow_x" axis="1 0 0" range="-180 180" stiffness="300" damping="30" armature=".01"/>
                  <joint name="left_elbow_y" axis="0 1 0" range="-180 180" stiffness="300" damping="30" armature=".01"/>
                  <joint name="left_elbow_z" axis="0 0 1" range="-180 180" stiffness="300" damping="30" armature=".01"/>
                  <inertial pos="0.11633361257610537 0.028649489285974567 -0.0004144518882862588" quat="1 0 0 0" mass="1.0" diaginertia="1e-05 1e-05 1e-05"></inertial>
                  <geom name="left_lower_arm" type="mesh" pos="0.11633361257610537 0.028649489285974567 -0.0004144518882862588" mesh="left_lower_arm"/>

                  <body name="left_hand" pos="0.27160394191741943 0.02561309188604355 -0.0006483271718025208">
                    <joint name="left_wrist_x" axis="1 0 0" range="-180 180" stiffness="200" damping="20" armature=".01"/>
                    <joint name="left_wrist_y" axis="0 1 0" range="-180 180" stiffness="200" damping="20" armature=".01"/>
                    <joint name="left_wrist_z" axis="0 0 1" range="-180 180" stiffness="200" damping="20" armature=".01"/>
                    <inertial pos="0.07982255752119019 -0.008922063561938398 0.004720762202933231" quat="1 0 0 0" mass="0.5" diaginertia="1e-05 1e-05 1e-05"></inertial>
                    <geom name="left_hand_part_1_palm" type="mesh" pos="0.07982255752119019 -0.008922063561938398 0.004720762202933231" mesh="left_hand_part_1_palm"/>
                    <geom name="left_hand_part_2_finger" type="mesh" pos="0.07982255752119019 -0.008922063561938398 0.004720762202933231" mesh="left_hand_part_2_finger"/>
                  </body>
                </body>
              </body>
            </body>

            <body name="right_clavicle" pos="-0.04607690870761871 0.07681627571582794 -0.00852900743484497">
              <joint name="right_clavicle_x" axis="1 0 0" range="-180 180"  stiffness="400" damping="40" armature=".02"/>
              <joint name="right_clavicle_y" axis="0 1 0" range="-180 180" stiffness="400" damping="40" armature=".02"/>
              <joint name="right_clavicle_z" axis="0 0 1" range="-180 180" stiffness="400" damping="40" armature=".02"/>
              <inertial pos="-0.10897205028885713 0.044662441279706984 -0.045913898455038404" quat="1 0 0 0" mass="1.0" diaginertia="1e-05 1e-05 1e-05"></inertial>
              <geom name="right_clavicle" type="mesh" pos="-0.10897205028885713 0.044662441279706984 -0.045913898455038404" mesh="right_clavicle"/>

              <body name="right_upper_arm" pos="-0.1303553283214569 0.058849237859249115 -0.012586284428834915">
                <joint name="right_shoulder_x" axis="1 0 0" range="-180 180"  stiffness="400" damping="40" armature=".02"/>
                <joint name="right_shoulder_y" axis="0 1 0" range="-180 180" stiffness="400" damping="40" armature=".02"/>
                <joint name="right_shoulder_z" axis="0 0 1" range="-180 180" stiffness="400" damping="40" armature=".02"/>
                <inertial pos="-0.12907529256321734 -0.03625429239320581 -0.02903768054704749" quat="1 0 0 0" mass="1.5" diaginertia="1e-05 1e-05 1e-05"></inertial>
                <geom name="right_upper_arm" type="mesh" pos="-0.12907529256321734 -0.03625429239320581 -0.02903768054704749" mesh="right_upper_arm"/>

                <body name="right_lower_arm" pos="-0.2724926471710205 -0.04592560604214668 -0.032428935170173645">
                  <joint name="right_elbow_x" axis="1 0 0" range="-180 180" stiffness="300" damping="30" armature=".01"/>
                  <joint name="right_elbow_y" axis="0 1 0" range="-180 180" stiffness="300" damping="30" armature=".01"/>
                  <joint name="right_elbow_z" axis="0 0 1" range="-180 180" stiffness="300" damping="30" armature=".01"/>
                  <inertial pos="-0.10197029606460631 -0.0005091530519303228 -0.012317895146602007" quat="1 0 0 0" mass="1.0" diaginertia="1e-05 1e-05 1e-05"></inertial>
                  <geom name="right_lower_arm" type="mesh" pos="-0.10197029606460631 -0.0005091530519303228 -0.012317895146602007" mesh="right_lower_arm"/>

                  <body name="right_hand" pos="-0.2633793354034424 2.8681010007858276e-05 -0.011822231113910675">
                    <joint name="right_wrist_x" axis="1 0 0" range="-180 180" stiffness="200" damping="20" armature=".01"/>
                    <joint name="right_wrist_y" axis="0 1 0" range="-180 180" stiffness="200" damping="20" armature=".01"/>
                    <joint name="right_wrist_z" axis="0 0 1" range="-180 180" stiffness="200" damping="20" armature=".01"/>
                    <inertial pos="-0.0774482034197786 -0.012316402889919153 0.0036101045285670025" quat="1 0 0 0" mass="0.5" diaginertia="1e-05 1e-05 1e-05"></inertial>
                    <geom name="right_hand_part_1_palm" type="mesh" pos="-0.0774482034197786 -0.012316402889919153 0.0036101045285670025" mesh="right_hand_part_1_palm"/>
                    <geom name="right_hand_part_2_finger" type="mesh" pos="-0.0774482034197786 -0.012316402889919153 0.0036101045285670025" mesh="right_hand_part_2_finger"/>
                  </body>
                </body>
              </body>
            </body>
          </body>
        </body>
      </body>
    </body>
  </worldbody>

  <actuator>
    <motor name='abdomen_x'       	gear='200' 	joint='abdomen_x'/>
    <motor name='abdomen_y'       	gear='200' 	joint='abdomen_y'/>
    <motor name='abdomen_z'       	gear='200' 	joint='abdomen_z'/>
    <motor name='spine_x'       	  gear='200' 	joint='spine_x'/>
    <motor name='spine_y'       	  gear='200' 	joint='spine_y'/>
    <motor name='spine_z'       	  gear='200' 	joint='spine_z'/>
    <motor name='chest_x'       	  gear='200' 	joint='chest_x'/>
    <motor name='chest_y'       	  gear='200' 	joint='chest_y'/>
    <motor name='chest_z'       	  gear='200' 	joint='chest_z'/>
    <motor name='neck_x'            gear='50' 	joint='neck_x'/>
    <motor name='neck_y'            gear='50' 	joint='neck_y'/>
    <motor name='neck_z'            gear='50' 	joint='neck_z'/>
    <motor name='head_x'            gear='50' 	joint='head_x'/>
    <motor name='head_y'            gear='50' 	joint='head_y'/>
    <motor name='head_z'            gear='50' 	joint='head_z'/>
    <motor name='left_hip_x'       	gear='200' 	joint='left_hip_x'/>
    <motor name='left_hip_y'       	gear='200' 	joint='left_hip_y'/>
    <motor name='left_hip_z'       	gear='200' 	joint='left_hip_z'/>
    <motor name='left_knee_x'       gear='150' 	joint='left_knee_x'/>
    <motor name='left_knee_y'       gear='150' 	joint='left_knee_y'/>
    <motor name='left_knee_z'       gear='150' 	joint='left_knee_z'/>
    <motor name='left_ankle_x'      gear='90' 	joint='left_ankle_x'/>
    <motor name='left_ankle_y'      gear='90' 	joint='left_ankle_y'/>
    <motor name='left_ankle_z'      gear='90' 	joint='left_ankle_z'/>
    <motor name='right_hip_x'       gear='200' 	joint='right_hip_x'/>
    <motor name='right_hip_y'       gear='200' 	joint='right_hip_y'/>
    <motor name='right_hip_z'       gear='200' 	joint='right_hip_z'/>
    <motor name='right_knee_x'      gear='150' 	joint='right_knee_x'/>
    <motor name='right_knee_y'      gear='150' 	joint='right_knee_y'/>
    <motor name='right_knee_z'      gear='150' 	joint='right_knee_z'/>
    <motor name='right_ankle_x'     gear='90' 	joint='right_ankle_x'/>
    <motor name='right_ankle_y'     gear='90' 	joint='right_ankle_y'/>
    <motor name='right_ankle_z'     gear='90' 	joint='right_ankle_z'/>
    <motor name='left_clavicle_x' 	gear='100' 	joint='left_clavicle_x'/>
    <motor name='left_clavicle_y' 	gear='100' 	joint='left_clavicle_y'/>
    <motor name='left_clavicle_z' 	gear='100' 	joint='left_clavicle_z'/>
    <motor name='left_shoulder_x' 	gear='100' 	joint='left_shoulder_x'/>
    <motor name='left_shoulder_y' 	gear='100' 	joint='left_shoulder_y'/>
    <motor name='left_shoulder_z' 	gear='100' 	joint='left_shoulder_z'/>
    <motor name='left_elbow_x'      gear='70' 	joint='left_elbow_x'/>
    <motor name='left_elbow_y'      gear='70' 	joint='left_elbow_y'/>
    <motor name='left_elbow_z'      gear='70' 	joint='left_elbow_z'/>
    <motor name='left_wrist_x' 	    gear='50' 	joint='left_wrist_x'/>
    <motor name='left_wrist_y' 	    gear='50' 	joint='left_wrist_y'/>
    <motor name='left_wrist_z' 	    gear='50' 	joint='left_wrist_z'/>
    <motor name='right_clavicle_x' 	gear='100' 	joint='right_clavicle_x'/>
    <motor name='right_clavicle_y' 	gear='100' 	joint='right_clavicle_y'/>
    <motor name='right_clavicle_z' 	gear='100' 	joint='right_clavicle_z'/>
    <motor name='right_shoulder_x' 	gear='100' 	joint='right_shoulder_x'/>
    <motor name='right_shoulder_y' 	gear='100' 	joint='right_shoulder_y'/>
    <motor name='right_shoulder_z' 	gear='100' 	joint='right_shoulder_z'/>
    <motor name='right_elbow_x'     gear='70' 	joint='right_elbow_x'/>
    <motor name='right_elbow_y'     gear='70' 	joint='right_elbow_y'/>
    <motor name='right_elbow_z'     gear='70' 	joint='right_elbow_z'/>
    <motor name='right_wrist_x' 	  gear='50' 	joint='right_wrist_x'/>
    <motor name='right_wrist_y' 	  gear='50' 	joint='right_wrist_y'/>
    <motor name='right_wrist_z' 	  gear='50' 	joint='right_wrist_z'/>
  </actuator>

</mujoco>
